Workbook
Name Filters: 'Module Data'!$A$46:$A$47
Name PortableAppliances: 'Module Data'!$A$39:$A$43
Name KitchenRefrigeration: 'Module Data'!$A$25:$A$33
Name KitchenCooking: 'Module Data'!$A$15:$A$20
Name Laundry: 'Module Data'!$A$7:$A$11
Name KitchenCleaning: 'Module Data'!$A$36

Sheet BOM Loader
B1: 1) Insert structured bill of material. Ensure all Required Inputs are populated else the upload will fail. | R1: 1) Insert structured bill of material. Ensure all Required Inputs are populated else the upload will fail. | AC1: Hide | AD1: Hide | AE1: Hide | AF1: Hide | AG1: Hide | AH1: Hide | AI1: Hide
B2: 2) Save template in desired location. | R2: 2) Save template in desired location. | AC2: Upload Value | AD2: Upload Value | AE2: Upload Value | AF2: Upload Value | AG2: Upload Value | AH2: Upload Value | AI2: Upload Value
B3: 3) When loading an assembly part but BOM structure is unknown, create a single part and select the Type (column C) as Assembly. | R3: 3) When loading an assembly part but BOM structure is unknown, create a single part and select the Type (column C) as Assembly.
A5: aPriori Mapping | B5: Type | C5: Commodity Type | D5: Part Number | E5: Level | F5: Description | G5: Life Cycle State | H5: Version | I5: Quantity | J5: Production Volume | K5: Procurement Contact | L5: Engineering Contact | M5: Subsystem | N5: Module Type | O5: Windchill Package | P5: Process Control Code | Q5: Project Name | R5: Date | S5: Date Cost Model Needed | T5: Requested By | U5: Reason for Costing | V5: Primary Mfg Region | W5: VPE | X5: Economic Date | Y5: Product Line Name | Z5: Platform Family | AA5: Estimate Currency | AB5: Requestor Comments | AC5: Manually Costed | AD5: Scenario | AE5: Create Date | AF5: Date Cost Model Needed | AG5: Active | AH5: Annual Volume | AI5: Costing Status
A6: Data Type | B6: Standard Field | C6: UDA Searchable String | D6: Standard Field | E6: Standard Field | F6: Standard Field | H6: UDA String | I6: Standard Field | J6: UDA String | K6: UDA String | L6: UDA String | M6: UDA String | N6: UDA String | O6: UDA String | P6: UDA String | Q6: Standard Field | R6: UDA String | S6: UDA Searchable Date | T6: UDA Searchable String | U6: UDA String | V6: UDA String | W6: UDA String | X6: UDA String | Y6: Standard Field | Z6: UDA Searchable String | AA6: UDA String | AB6: UDA String | AC6: System Setting | AD6: UDA String | AE6: UDA String | AF6: UDA String | AH6: Standard Field | AI6: UDA Searchable String
A7: System Field | B7: type | C7: commodityType | D7: partNumber | E7: level | F7: description | H7: version | I7: quantity | J7: productionVolume | K7: procurementContact | L7: engineeringContact | M7: subsystem | N7: moduleType | O7: pkgNumber | P7: processControlCode | Q7: projectName | S7: dateCostModelNeeded | T7: requestedBy | U7: reasonForCosting | V7: primaryMfgRegion | W7: vpe | X7: economicDate | Y7: productLineName | Z7: platformFamily | AA7: estimateCurrency | AB7: requestorComments | AC7: manuallyCosted | AD7: scenario | AE7: createDate | AF7: dateCostModelNeeded | AG7: active | AH7: annualVolume | AI7: costing Status
A8: Predefined Values | B8: Yes | C8: Yes | P8: Yes | U8: Yes | V8: Yes | W8: Yes | X8: Yes | AA8: Yes | AH8: = Production Volume | AI8: Yes
A9: Required Input | B9: Yes | C9: Yes | D9: Yes | E9: Yes | F9: Yes | G9: No | H9: Yes | I9: Yes | J9: Yes | K9: Optional | L9: Optional | M9: Optional | N9: Optional | O9: Optional | P9: Yes | Q9: Yes | R9: Yes | S9: Yes | T9: Yes | U9: Yes | V9: Optional | W9: Yes | X9: Yes | Y9: Yes | Z9: Yes | AA9: Yes | AB9: Optional | AI9: Yes
A10: Defined Criteria | B10: Drop-down selection: Assembly Part | C10: pre-defined selection list | D10: Primary Key Free form text | E10: Level of BOM 1 2 3 and so on | F10: free form text | H10: Windchill CAD version or Package Number format = X.XX | J10: Numeric Value | K10: free form text | L10: free form text | P10: M = Make B = Buy S = Subcontract C = Co-location | Q10: free form text | R10: Enter today's date mm/dd/yyyy | S10: mm/dd/yyyy | T10: free form text | U10: pre-defined selection list | V10: pre-defined selection list | W10: pre-defined selection list *** if commodity is Motor then China should be selected VPE *** | X10: pre-defined selection list | Y10: Drop-down selection list | Z10: Selection list dependant on Product Line Name selection | AA10: Drop-down selection list | AB10: free form text | AC10: System Value to Allow Costing Process change | AD10: Formula Generated Version : Region | AE10: Formula Generated Date | AF10: Formula Generated Date | AG10: Always False | AH10: Numeric Value | AI10: Always Unassigned so Managers can search and assign to cost engineer
A11: =IFERROR(IF(B11=VLOOKUP(C11,$I$995:$J$1019,2,FALSE),"Error",""),"") | B11: Part | C11: Other | D11: 8318088 | E11: 1 | F11: Hinge, LH | H11: PKG 123699 | I11: 1 | J11: 120000 | K11: Karen Yohen Perez | L11: Sidhant Patnaik | O11: PKG 123699 | P11: B | Q11: Maverick CL | R11: =IF(D11 = "","", today()) -> 46066 | S11: =IF(D11 = "","", R11+14) -> 46080 | T11: Glenn Mudd | U11: Correlation | V11: USA | W11: NAR USA | X11: 2024 July | Y11: Laundry | Z11: Commercial Laundry | AA11: USD | AC11: =IF(J11>0,"False","") -> False | AD11: =IF(J11=0,"",H11&" "&W11&" "&X11) -> PKG 123699 NAR USA 2024 July | AE11: =if(J11=0,"",R11) -> 46066 | AF11: =if(J11=0,"",S11) -> 46080 | AG11: =IF(J11=0,"","False") -> False | AH11: =if(J11>0,J11,"") -> 120000 | AI11: =IF(J11=0,"","Unassigned") -> Unassigned
A20: =IFERROR(IF(B20=VLOOKUP(C20,$I$995:$J$1019,2,FALSE),"Error",""),"") | S20: =IF(D20 = "","", R20+14) | AI20: =IF(J20=0,"","Unassigned")
A21: =IFERROR(IF(B21=VLOOKUP(C21,$I$995:$J$1019,2,FALSE),"Error",""),"") | S21: =IF(D21 = "","", R21+14) | AI21: =IF(J21=0,"","Unassigned")
A22: =IFERROR(IF(B22=VLOOKUP(C22,$I$995:$J$1019,2,FALSE),"Error",""),"") | S22: =IF(D22 = "","", R22+14) | AI22: =IF(J22=0,"","Unassigned")
A23: =IFERROR(IF(B23=VLOOKUP(C23,$I$995:$J$1019,2,FALSE),"Error",""),"") | S23: =IF(D23 = "","", R23+14) | AI23: =IF(J23=0,"","Unassigned")
A24: =IFERROR(IF(B24=VLOOKUP(C24,$I$995:$J$1019,2,FALSE),"Error",""),"") | S24: =IF(D24 = "","", R24+14) | AI24: =IF(J24=0,"","Unassigned")
A25: =IFERROR(IF(B25=VLOOKUP(C25,$I$995:$J$1019,2,FALSE),"Error",""),"") | S25: =IF(D25 = "","", R25+14) | AI25: =IF(J25=0,"","Unassigned")
A26: =IFERROR(IF(B26=VLOOKUP(C26,$I$995:$J$1019,2,FALSE),"Error",""),"") | S26: =IF(D26 = "","", R26+14) | AI26: =IF(J26=0,"","Unassigned")
A27: =IFERROR(IF(B27=VLOOKUP(C27,$I$995:$J$1019,2,FALSE),"Error",""),"") | S27: =IF(D27 = "","", R27+14) | AI27: =IF(J27=0,"","Unassigned")
A28: =IFERROR(IF(B28=VLOOKUP(C28,$I$995:$J$1019,2,FALSE),"Error",""),"") | S28: =IF(D28 = "","", R28+14) | AI28: =IF(J28=0,"","Unassigned")
A29: =IFERROR(IF(B29=VLOOKUP(C29,$I$995:$J$1019,2,FALSE),"Error",""),"") | S29: =IF(D29 = "","", R29+14) | AI29: =IF(J29=0,"","Unassigned")
A30: =IFERROR(IF(B30=VLOOKUP(C30,$I$995:$J$1019,2,FALSE),"Error",""),"") | S30: =IF(D30 = "","", R30+14) | AI30: =IF(J30=0,"","Unassigned")
A31: =IFERROR(IF(B31=VLOOKUP(C31,$I$995:$J$1019,2,FALSE),"Error",""),"") | R31: =IF(D31 = "","", today()) | S31: =IF(D31 = "","", R31+14) | AC31: =IF(J31>0,"False","") | AD31: =IF(J31=0,"",H31&" "&W31&" "&X31) | AE31: =if(J31=0,"",R31) | AF31: =if(J31=0,"",S31) | AG31: =IF(J31=0,"","False") | AH31: =if(J31>0,J31,"") | AI31: =IF(J31=0,"","Unassigned")
A32: =IFERROR(IF(B32=VLOOKUP(C32,$I$995:$J$1019,2,FALSE),"Error",""),"") | R32: =IF(D32 = "","", today()) | S32: =IF(D32 = "","", R32+14) | AC32: =IF(J32>0,"False","") | AD32: =IF(J32=0,"",H32&" "&W32&" "&X32) | AE32: =if(J32=0,"",R32) | AF32: =if(J32=0,"",S32) | AG32: =IF(J32=0,"","False") | AH32: =if(J32>0,J32,"") | AI32: =IF(J32=0,"","Unassigned")
A33: =IFERROR(IF(B33=VLOOKUP(C33,$I$995:$J$1019,2,FALSE),"Error",""),"") | R33: =IF(D33 = "","", today()) | S33: =IF(D33 = "","", R33+14) | AC33: =IF(J33>0,"False","") | AD33: =IF(J33=0,"",H33&" "&W33&" "&X33) | AE33: =if(J33=0,"",R33) | AF33: =if(J33=0,"",S33) | AG33: =IF(J33=0,"","False") | AH33: =if(J33>0,J33,"") | AI33: =IF(J33=0,"","Unassigned")
A34: =IFERROR(IF(B34=VLOOKUP(C34,$I$995:$J$1019,2,FALSE),"Error",""),"") | R34: =IF(D34 = "","", today()) | S34: =IF(D34 = "","", R34+14) | AC34: =IF(J34>0,"False","") | AD34: =IF(J34=0,"",H34&" "&W34&" "&X34) | AE34: =if(J34=0,"",R34) | AF34: =if(J34=0,"",S34) | AG34: =IF(J34=0,"","False") | AH34: =if(J34>0,J34,"") | AI34: =IF(J34=0,"","Unassigned")
A35: =IFERROR(IF(B35=VLOOKUP(C35,$I$995:$J$1019,2,FALSE),"Error",""),"") | R35: =IF(D35 = "","", today()) | S35: =IF(D35 = "","", R35+14) | AC35: =IF(J35>0,"False","") | AD35: =IF(J35=0,"",H35&" "&W35&" "&X35) | AE35: =if(J35=0,"",R35) | AF35: =if(J35=0,"",S35) | AG35: =IF(J35=0,"","False") | AH35: =if(J35>0,J35,"") | AI35: =IF(J35=0,"","Unassigned")
A36: =IFERROR(IF(B36=VLOOKUP(C36,$I$995:$J$1019,2,FALSE),"Error",""),"") | R36: =IF(D36 = "","", today()) | S36: =IF(D36 = "","", R36+14) | AC36: =IF(J36>0,"False","") | AD36: =IF(J36=0,"",H36&" "&W36&" "&X36) | AE36: =if(J36=0,"",R36) | AF36: =if(J36=0,"",S36) | AG36: =IF(J36=0,"","False") | AH36: =if(J36>0,J36,"") | AI36: =IF(J36=0,"","Unassigned")
A37: =IFERROR(IF(B37=VLOOKUP(C37,$I$995:$J$1019,2,FALSE),"Error",""),"") | R37: =IF(D37 = "","", today()) | S37: =IF(D37 = "","", R37+14) | AC37: =IF(J37>0,"False","") | AD37: =IF(J37=0,"",H37&" "&W37&" "&X37) | AE37: =if(J37=0,"",R37) | AF37: =if(J37=0,"",S37) | AG37: =IF(J37=0,"","False") | AH37: =if(J37>0,J37,"") | AI37: =IF(J37=0,"","Unassigned")
A38: =IFERROR(IF(B38=VLOOKUP(C38,$I$995:$J$1019,2,FALSE),"Error",""),"") | R38: =IF(D38 = "","", today()) | S38: =IF(D38 = "","", R38+14) | AC38: =IF(J38>0,"False","") | AD38: =IF(J38=0,"",H38&" "&W38&" "&X38) | AE38: =if(J38=0,"",R38) | AF38: =if(J38=0,"",S38) | AG38: =IF(J38=0,"","False") | AH38: =if(J38>0,J38,"") | AI38: =IF(J38=0,"","Unassigned")
A39: =IFERROR(IF(B39=VLOOKUP(C39,$I$995:$J$1019,2,FALSE),"Error",""),"") | R39: =IF(D39 = "","", today()) | S39: =IF(D39 = "","", R39+14) | AC39: =IF(J39>0,"False","") | AD39: =IF(J39=0,"",H39&" "&W39&" "&X39) | AE39: =if(J39=0,"",R39) | AF39: =if(J39=0,"",S39) | AG39: =IF(J39=0,"","False") | AH39: =if(J39>0,J39,"") | AI39: =IF(J39=0,"","Unassigned")
A40: =IFERROR(IF(B40=VLOOKUP(C40,$I$995:$J$1019,2,FALSE),"Error",""),"") | R40: =IF(D40 = "","", today()) | S40: =IF(D40 = "","", R40+14) | AC40: =IF(J40>0,"False","") | AD40: =IF(J40=0,"",H40&" "&W40&" "&X40) | AE40: =if(J40=0,"",R40) | AF40: =if(J40=0,"",S40) | AG40: =IF(J40=0,"","False") | AH40: =if(J40>0,J40,"") | AI40: =IF(J40=0,"","Unassigned")
A41: =IFERROR(IF(B41=VLOOKUP(C41,$I$995:$J$1019,2,FALSE),"Error",""),"") | R41: =IF(D41 = "","", today()) | S41: =IF(D41 = "","", R41+14) | AC41: =IF(J41>0,"False","") | AD41: =IF(J41=0,"",H41&" "&W41&" "&X41) | AE41: =if(J41=0,"",R41) | AF41: =if(J41=0,"",S41) | AG41: =IF(J41=0,"","False") | AH41: =if(J41>0,J41,"") | AI41: =IF(J41=0,"","Unassigned")
A42: =IFERROR(IF(B42=VLOOKUP(C42,$I$995:$J$1019,2,FALSE),"Error",""),"") | R42: =IF(D42 = "","", today()) | S42: =IF(D42 = "","", R42+14) | AC42: =IF(J42>0,"False","") | AD42: =IF(J42=0,"",H42&" "&W42&" "&X42) | AE42: =if(J42=0,"",R42) | AF42: =if(J42=0,"",S42) | AG42: =IF(J42=0,"","False") | AH42: =if(J42>0,J42,"") | AI42: =IF(J42=0,"","Unassigned")
... A499: =IFERROR(IF(B499=VLOOKUP(C499,$I$995:$J$1019,2,FALSE),"Error",""),"") | R499: =IF(D499 = "","", today()) | S499: =IF(D499 = "","", R499+14) | AC499: =IF(J499>0,"False","") | AD499: =IF(J499=0,"",H499&" "&W499&" "&X499) | AE499: =if(J499=0,"",R499) | AF499: =if(J499=0,"",S499) | AG499: =IF(J499=0,"","False") | AH499: =if(J499>0,J499,"") | AI499: =IF(J499=0,"","Unassigned")
R500: =IF(D500 = "","", today()) | S500: =IF(D500 = "","", R500+14)
R501: =IF(D501 = "","", today()) | S501: =IF(D501 = "","", R501+14)
R502: =IF(D502 = "","", today()) | S502: =IF(D502 = "","", R502+14)
R503: =IF(D503 = "","", today()) | S503: =IF(D503 = "","", R503+14)
R504: =IF(D504 = "","", today()) | S504: =IF(D504 = "","", R504+14)
I995: Assembly - Plastic | J995: Part
...

Sheet Data Validation
A1: TC Analysts | B1: Currency | C1: ProcessControlCode | F1: ReasonforCosting | G1: EconomicDate | H1: Type | I1: PrimaryMfgRegion | J1: CommodityType | K1: CostingStatus | L1: vpe
A2: Aaron Cunningham | B2: USD | C2: M | F2: Area 1 | G2: 2024 July | H2: Assembly | I2: USA | J2: Assembly - Plastic | K2: Unassigned | L2: NAR USA
A3: Allison Vanderveld | B3: INR | C3: B | F3: Design Change | G3: 2024 January | H3: Part | I3: Argentina | J3: Assembly - Metals | L3: NAR Mexico
A4: Anima Srivastava | B4: ARS | C4: S | D4: ProductLine | F4: New Technology | G4: 2023 July | I4: Brazil | J4: Electromechanical | L4: Asia China
A5: Anuj Malhotra | B5: BRL | C5: C | D5: Laundry | F5: Tradeoff Study | G5: 2023 January | I5: Canada | J5: Electronic | L5: Asia Thailand
A6: Arkadiusz Szala | B6: COP | D6: Kitchen - Cooking | F6: Modeled Cost | G6: 2022 October | I6: China | J6: PCBA | L6: Asia Vietnam
A7: Brad Bumgardner | B7: CNY | D7: Kitchen - Refrigeration | E7: x | F7: Correlation | G7: 2022 July | I7: Colombia | J7: HMI | L7: EMEA Italy
A8: Cailine Huang | B8: EUR | D8: Kitchen - Cleaning | E8: x | F8: SSC/SSI | G8: 2021 January | I8: France | J8: Glass | L8: EMEA Poland
A9: Caio Aggio | B9: PLN | D9: Portable Appliances | E9: x | F9: Initial Estimate | G9: 2020 July | I9: Germany | J9: Harness | L9: EMEA Romania
A10: Candy He | B10: RON | D10: Filters | E10: x | G10: 2020 January | I10: India | J10: Heater | L10: EMEA Russia
A11: Cinzia Cozzi | B11: RUB | E11: x | G11: 2019 July | I11: Italy | J11: Metal - Stamping | L11: EMEA Slovakia
A12: Claudemir Carvalho | B12: THB | G12: 2019 January | I12: Japan | J12: Metal - Die Casting | L12: EMEA Turkey
A13: Giovanni Mezzopera | B13: TRY | G13: 2018 July | I13: Korea | J13: Metal - Bar Turned | L13: Asia Pune
A14: Glenn Mudd | B14: VND | G14: 2018 January | I14: Mexico | J14: Metal - Forged | L14: Asia Pondicherry
A15: Gunner Wang | B15: ZAR | E15: x | G15: 2017 July | I15: Poland | J15: Motor | L15: Asia Faridabad
A16: Gustavo Bortolini | B16: GBP | E16: x | G16: 2017 January | I16: Romania | J16: EPS | L16: LAR Argentina
A17: Jeff Haselhoff | E17: x | I17: Russia | J17: Carton | L17: LAR Brazil
A18: Joe Knecht | E18: x | I18: Slovakia | J18: Assembly - Carton | L18: LAR Colombia
A19: Kaitlyn Becker | E19: x | I19: Switzerland | J19: Packaging / Literature | L19: EMEA UK
A20: Katarzyna Kobus | E20: x | I20: Thailand | J20: Plastic
A21: Keith Westbrook | I21: Turkey | J21: Rubber
A22: Luis Kohntopp | I22: Vietnam | J22: Valve
A23: Lukasz Rembiecha | J23: Compressor
A24: Mani Ganesan | J24: Cooling Assembly
A25: Marco Stura | J25: Other
A26: Melody Chi | E26: x | J26: Fastener
A27: Norman Zhu
A28: Ricardo Swarowski
A29: Ruvitha Poojary
A30: Thambi
A31: Veronica Rizzello
E33: x

Sheet Module Data
C1: Fabric Care | E1: Dryer | G1: Horizontal Axis | I1: Vertical Axis | K1: Food Preparation | M1: Built In Oven | O1: Built In Cooktop | Q1: FS Range | S1: MWO BI | U1: Warming Drawer | W1: Dishwashers | AA1: Portables | AE1: Refrigeration
C3: Subsystem | K3: Subsystem | M3: Module Type | W3: Subsystem | Y3: Module Type | AA3: Subsystem | AE3: Subsystem | AG3: Module Type
A4: Product Line Platform | E4: Module Type
K5: BuiltInOven
A6: Laundry | C6: Dryer | E6: Aesthetics | G6: Aesthetics | I6: Aesthetics | J6: x | K6: Cabinet BIO | M6: CabinetBIO | O6: ControlsBIC | Q6: CabinetFSR | S6: CabinetMicrowave | U6: CabinetWD | W6: Dishwashers | Y6: CabinetDishwasher | AA6: Blender | AC6: BowlsAndJars | AE6: BottomMount | AG6: CabinetFSS | AI6: AirConditioner
A7: Dryer | B7: x | C7: Aesthetics | E7: Console and HMI | G7: Console and HMI | I7: Console and HMI | J7: x | K7: Cavity BIO | M7: Cavity Mounts | O7: Appliance Control Unit | Q7: Chassis Top | S7: Cabinet - Microwave | U7: Chassis Top | W7: Cabinet Dishwasher | Y7: Counter Weights | AA7: Bowls And Jars | AC7: Blades | AE7: Cabinet FSS | AG7: Cabinet Outer | AI7: Cabinet AC
A8: HA Washer | B8: x | C8: Dry Chassis | E8: Door | G8: Door and Entrance | I8: Enclosure and Structure | J8: x | K8: Controls | M8: Chassis Top | O8: Power Cords | Q8: Frame - Front | S8: Component Carrier | U8: Consoles | W8: Controls Dishwasher | Y8: Drip Trays | AA8: Cabinet Enclosure | AC8: Jars | AE8: Controls FSS | AG8: Hinges | AI8: Controls AC
A9: VA Washer | B9: x | C9: Dry System | E9: Top and Front Panel | I9: Lid | J9: x | K9: Documentation | M9: Panels - Back | O9: User Interface | Q9: Panels - Back | S9: Motor Unit - Turn Table | U9: Panels - Back | W9: Dispensing System DW | Y9: Panels - Side | AA9: Controls Blender | AC9: Lids - Jar | AE9: Cooling System | AG9: Liners - Cabinet Freezer Compartment | AI9: Cooling System AC
A10: FSOU | B10: x | C10: EES | G10: EES | I10: Lid Entrance | J10: x | K10: Door Oven | M10: Panels - Side | O10: Wire Harness | Q10: Panels - Side | S10: Power Cords | U10: Panels - Side | W10: Documentation DW | Y10: Panels - Toe | AA10: Documentation | AE10: Documentation | AG10: Liners - Cabinet Refrigerator Compartment | AI10: Documentation
A11: Commercial Laundry | E11: Dry Chassis | G11: Actuator | I11: Top and Front Panel | J11: x | K11: Packaging | M11: Structure Base | Q11: Structure Base | S11: Structural Brackets | U11: Trims Gap | W11: Door DW | Y11: Plinth Panel | AA11: Drive System Blender | AC11: CabinetEnclosure | AE11: Door And Drawer | AG11: Mounting Plates Compressor | AI11: Packaging
C12: HA Washer | E12: Cab Enclosure | G12: ACU | J12: x | K12: UI Console BIO | M12: Structure Feet | O12: Cooktop | Q12: Structure Feet | S12: Switches Door | W12: Dry System | Y12: Table Tops | AA12: Packaging | AC12: Brand Badges | AE12: Ice And Water | AG12: Pedestal
C13: Aesthetics | E13: Drum | G13: Heater | I13: EES | J13: x | K13: Ventilation BIO | M13: Trims Gap | O13: Burner Box | Q13: Trims Gap | S13: Valves - Safety | U13: CavityWD | W13: Hydraulic System Distribution | AC13: Cabinet Housing | AE13: Interior Space Management
A14: Kitchen - Cooking | C14: EES | E14: Heat System | G14: Light | I14: ACU | O14: Burner Coils | U14: Bake Pans | W14: Hydraulic System Drain Assembly | Y14: ControlsDishwasher | AE14: Packaging | AG14: ControlsFSS | AI14: CabinetAC
A15: CT - Cooktop | C15: Wash Chassis | E15: Packaging | G15: Literature | I15: Console and HMI | K15: BuiltInCooktop | M15: CavityBIO | O15: Burners Induction | Q15: CavityFSR | S15: CavityMicrowave | U15: Cavity Insulation | W15: Hydraulic System Fill | Y15: Appliance Control Unit | AC15: ControlsBlender | AG15: Appliance Control Unit | AI15: Cabinet Outer
A16: FSR - Free Standing Range | C16: Wash System | E16: Panels - Top | G16: Sensor | I16: Literature | J16: x | K16: Controls BIC | M16: Bake Pans | O16: Burners Radiant | Q16: Bake Pans | S16: Cavity - Microwave | U16: Cavity Oven | W16: Hydraulic System Pump Sump Assembly And Heater | Y16: External Communication | AC16: Power Cords | AG16: Lighting Unit | AI16: Panels - Front
A17: HD - Hoods | E17: Trim Parts - Entrance | G17: Wire and Cable | I17: Wire and Cable | J17: x | K17: Cooktop | M17: Cavity Insulation | O17: Burners Surface | Q17: Burner Gas Oven | S17: Cavity Insulation | U17: Frame - Front | W17: Interior Space Management Racks | Y17: Junction Box | AC17: User Interface | AE17: SidebySide | AG17: Lighting Unit - LED | AI17: Separators Cabinet
A18: WO - Wall Ovens | C18: VA Washer | J18: x | K18: Documentation | M18: Cavity Oven | O18: Detection Flame | Q18: Cavity Insulation | S18: Door Structures | U18: Gaskets Door | W18: Interior Space Management Rails And Adjuster | Y18: Power Supply | AE18: Cabinet FSS | AG18: Power Cords | AI18: Structure Base
A19: BIMW - built-In Microwave | C19: Aesthetics | J19: x | K19: Packaging | M19: Cover Convect | O19: Glass Top | Q19: Cavity Oven | S19: Forced Convection | U19: Heating Electric Bottom | W19: Packaging | Y19: Sensor Pack | AC19: DriveSystemBlender | AE19: Controls FSS | AG19: Power Supply
A20: MWO - Microwave | C20: EES | G20: Wash Chassis | J20: x | K20: UI Console BIC | M20: Fans Cavity | O20: Grates | Q20: Cover Convect | S20: Frame - Microwave Oven Door Inner | U20: Lighting Unit | W20: Sound Reduction | Y20: Timers | AC20: Couplings | AE20: Cooling System | AG20: Switches Door | AI20: ControlsAC
C21: Wash Chassis | E21: CabinetEnclosureDryer | G21: Powertrain | I21: Wash Chassis | J21: x | K21: Ventilation BIC | M21: Frame - Front | O21: Housing Induction | Q21: Fans Cavity | S21: Heating Electric Bottom | W21: Tub Assembly | Y21: User Interface | AC21: Motors -Drive | AE21: Documentation | AG21: Timers | AI21: Power Supply
B22: x | C22: Wash System | E22: Cabinet Bottom | G22: Structure | I22: Cabinet Washer | M22: Gaskets Door | O22: Ignitors | Q22: Gaskets Door | S22: Heating Electric Top | U22: ControlsWD | Y22: Wire Harness | AE22: Door And Drawer | AG22: User Interface | AI22: User Interface
B23: x | E23: Panels - Back | G23: Suspension | I23: Packaging | K23: FreestandingRange | M23: Heat Shields | O23: Manifold Gas | Q23: Heat Shields | S23: Hinges | U23: Appliance Control Unit | AE23: Ice And Water | AG23: Wire Harness | AI23: Wire Harness
A24: Kitchen - Refrigeration | B24: x | E24: Panels - Side | G24: Wash Unit | I24: Powertrain | J24: x | K24: Cabinet FSR | M24: Heating Electric Back | O24: Metal Top | Q24: Heating Electric Back | S24: Hooks Door | U24: Power Cords | Y24: DispensingSystemDW | AA24: Standmixer | AC24: BowlsAndJarsStandmixer | AE24: Interior Space Management
A25: BM - Bottom Mount | B25: x | E25: U Wrap | G25: Packaging | I25: Spin Algorithims | J25: x | K25: Cavity FSR | M25: Heating Electric Bottom | O25: Mount Plates | Q25: Heating Electric Bottom | S25: Lighting Unit | U25: Sensors - Temperature | Y25: Dispenser - Chemistry | AA25: Bowls And Jars Standmixer | AC25: Bowls | AE25: Packaging | AG25: CoolingSystem | AI25: CoolingSystemAC
A26: FDBM - French Door Bottom Mount | I26: Suspension | J26: x | K26: Controls | M26: Heating Electric Top | O26: Piping Gas | Q26: Heating Electric Top | S26: Magnetrons | U26: User Interface | AA26: Cabinet Enclosure Standmixer | AC26: Lids - Bowl | AG26: Accumulators | AI26: Compressors
A27: SBS - Side by Side | B27: x | E27: ControlsDryer | G27: Wash System | I27: Wash Unit | J27: x | K27: Cooktop FSR | M27: Lighting Unit | O27: Source Gas | Q27: Lighting Unit | S27: Stirrer Antennas | U27: Wire Harness | Y27: DocumentationDW | AA27: Controls Blender Standmixer | AG27: Compressors | AI27: Condensers Forced
A28: BIR - Built in Refrigerator | B28: x | E28: Appliance Control Unit | G28: Bulk Dispense | J28: x | K28: Documentation | M28: Racks Shelf | O28: Trims Gap | Q28: Piping Gas | S28: Turn Table | Y28: Documentation | AA28: Documentation | AC28: CabinetEnclosureStandmixer | AE28: SingleDoor | AG28: Condensers Clinched | AI28: Ducts - Air Flow
A29: IM - Ice Make | B29: x | E29: Inverters | G29: Dry System | J29: x | K29: Door FSR | M29: Racks Side | O29: Valves Gas | Q29: Racks Shelf | S29: Valves Forced Convection | U29: DoorWD | Y29: Installation And Accessories Pack | AA29: Drive System Standmixer | AC29: Brand Badges | AE29: Cabinet FSS | AG29: Condensers External | AI29: Evaporators Fin On Tube
A30: TM - Top Mount | B30: x | E30: Lighting Unit | G30: Inlet | J30: x | K30: Drawer | M30: Reflectors | Q30: Racks Side | U30: Brand Badges | AA30: Packaging | AC30: Cabinet Base | AE30: Controls FSS | AG30: Condensers Forced | AI30: Fan And Motor - Air Flow
A31: SD - Single Door | B31: x | E31: Power Cords | G31: Outlet Recirc | I31: Wash System | J31: x | K31: Packaging | M31: Steamer | O31: UIConsoleBIC | Q31: Reflectors | S31: ControlsMicrowave | U31: Gaskets Door | Y31: DoorDW | AC31: Cabinet Housing | AE31: Cooling System | AG31: Condensers Pre | AI31: Tubing - Connector
A32: UF - Upright Freezer | E32: Power Supply | G32: Ventilation | I32: Clothes Mover | J32: x | K32: UI Console FSR | M32: Trays Hidden Bake | O32: Knobs And Buttons | Q32: Source Gas | S32: Appliance Control Unit | U32: Handles Door | Y32: Brand Badges | AC32: Locks Door - Mechanical | AE32: Documentation | AG32: Condensers Skin | AI32: Valves - Refrigerant
A33: CF - Chest Freezer | E33: RFI Filters | G33: Wash Process | I33: Dispenser | J33: x | K33: Ventilation FSR | Q33: Steamer | S33: Inverters | Y33: Consoles | AC33: Support - Bowl | AE33: Door And Drawer | AG33: Cover Evaporator
E34: Sensors - Control Board | I34: Heater and Steamer Algorithim | M34: Controls | O34: VentilationBIC | Q34: Trays Hidden Bake | S34: Magnetron Power Generation | U34: DrawerWD | Y34: Door Balance | AE34: Ice And Water | AG34: Dampers -Air
A35: Kitchen - Cleaning | E35: Switches - Modifier | I35: Hydraulic System | K35: MicrowaveOvenBuiltIn | M35: Appliance Control Unit | O35: Blowers | Q35: Valves Gas | S35: Mains Filter | U35: Brand Badges | Y35: Door Inner | AC35: ControlsBlenderStandmixer | AE35: Interior Space Management | AG35: Defrost Drain
A36: Dishwasher | E36: Timers | I36: Inlet | J36: x | K36: Cabinet Microwave | M36: Locks Door - Mechanical | O36: Exhaust Vent | S36: Power Supply | U36: Drawer Bin | Y36: Door Outer | AC36: Appliance Control Unit | AE36: Packaging | AG36: Drier Refrigerant
E37: User Interface | I37: Outlet and Recirculation | J37: x | K37: Cavity Microwave | M37: Power Cords | Q37: CooktopFSR | S37: Sensors - Humidity | U37: Drawers Front | Y37: Handles Door | AC37: Power Cords | AG37: Electric Heaters
A38: PortableAppliances | E38: Wire Harness | I38: Wash Unit | J38: x | K38: Controls Microwave | M38: Sensors - Humidity | Q38: Burner Coils | S38: Sensors - Temperature | U38: Glides Drawer | Y38: Latches Door | AG38: Evaporators Direct Cool
A39: Blender | I39: Outlet Recirc | J39: x | K39: Documentation | M39: Sensors - Temperature | Q39: Burners Induction | S39: Timers | U39: Handles Door | Y39: User Interface - Mechanical | AC39: DriveSystemStandmixer | AE39: TopMount | AG39: Evaporators Fin On Tube
A40: Kettle | E40: DispensingSystem | J40: x | K40: Door Microwave | M40: User Interface | Q40: Burners Radiant | S40: User Interface | AC40: Motors -Drive | AE40: Cabinet FSS | AG40: Fans Evaporator
A41: Hand Mixer | E41: Control Unit - Dispenser | J41: x | K41: Packaging | M41: Wire Harness | Q41: Burners Surface | S41: Wire Harness | U41: VentilationWD | Y41: DrySystem | AC41: Planetary Output | AE41: Controls FSS | AG41: Fans Forced Condenser
...

Sheet PA Viewer Extract Summary View
A1: Product Group | B1: Modular System Group | C1: Module Set Type | D1: Module Types
A2: Air Treatment
B3: Window Room Air Conditioners
C4: Cabinet
D5: Cabinet Outer
D6: Panels - Front
D7: Separators Cabinet
D8: Structure Base
C9: Controls
D10: Power Supply
D11: User Interface
D12: Wire Harness
C13: Cooling System
D14: Compressors
D15: Condensers Forced
D16: Ducts - Air Flow
D17: Evaporators Fin On Tube
D18: Fan And Motor - Air Flow
D19: Tubing - Connector
D20: Valves - Refrigerant
C21: Documentation
D22: Documentation
D23: Installation And Accessories Pack
C24: Packaging
D25: Packaging
A26: Fabric Care
B27: Dryers
C28: Blower
D29: Blower Wheels
D30: Exhaust Duct Blower
D31: Housing Blower
D32: Lint Filters
D33: Motor And Bracket Blower
C34: Cabinet - Aesthetic
D35: Door Outer
D36: Handles Drawer
D37: Panels - Front
D38: Panels - Toe
D39: Panels - Top
D40: Trim Parts - Entrance
...

Sheet Imports
A1: aPriori Data Type | B1: Standard Field | C1: Standard Field | D1: Standard Field | E1: Standard Field | F1: Standard Field | G1: UDA String | H1: UDA String | I1: Standard Field | J1: UDA Searchable String | K1: UDA String | L1: UDA String | M1: Standard Field | N1: Standard Field | O1: Standard Field | P1: UDA Searchable Date | Q1: UDA Searchable Date | R1: UDA Searchable String | S1: UDA Searchable String | T1: UDA String | V1: UDA String | W1: UDA String | X1: UDA String | Y1: UDA String | Z1: UDA String
A2: aPriori Mapping | B2: Level | C2: Part Number | D2: Description | E2: Quantity | F2: Revision | H2: Process Control Code | I2: Product Line | J2: Product Line Platform | K2: Subsystem | L2: Module | M2: Project Name | N2: Quoted Annual Volume | O2: Quoted Currency | P2: Date Cost Model Needed | Q2: Target Completion Date | R2: Requested By | S2: Commodity Type | T2: Reason for Costing | U2: Costing Engineer | V2: Procurement Contact | W2: Engineering Contact | X2: Primary Mfg Region | Z2: Analyst Comments
A3: Whirlpool Field | B3: Level | C3: Item Number | D3: Item Description | E3: Qty | F3: Part Rev Level | G3: Windchill Iteration | H3: Process Control Code | I3: Product Group | J3: Modular System: chg to Platform Family | K3: Module Set | L3: Module; chg to Module Type | M3: Project Name | N3: Production Volume | O3: Cost Estimate Currency | P3: Date Cost Model Needed | Q3: Target Completion Date | R3: Requested By | S3: Material | T3: Reason For Costing | V3: Procurement Contact | W3: Engineering Contact | X3: Production Region | Y3: Economic Date | Z3: Requestor Comments
A4: Admin Info | T4: Change to Cost Type
A5: Required Input | B5: Yes | C5: Yes | D5: Yes | E5: Yes | F5: Yes | H5: Yes | I5: Optional | J5: Optional | M5: Optional | N5: Yes | O5: Yes | P5: Yes | Q5: Workflow | R5: Yes | S5: Output Only | T5: Yes | U5: Required | V5: Optional | W5: Optional | X5: Yes | Y5: Yes | Z5: Option
A6: Defined Criteria | G6: x.xx | H6: M, B, Z, X, S
H9: M | I9: Fabric Care | J9: AT - Air Treatment | K9: Blower | L9: Accessories - Basket | O9: USD | S9: Assembly | T9: Area 1 | U9: Joe Larson | X9: USA | Y9: 41275
H10: B | I10: Food Preparation | J10: FC - Dryer | K10: Bowls And Jars | L10: Accumulators | O10: INR | S10: Electromechanical | T10: Design Change | U10: Jeff Miller | X10: Mexico | Y10: 41456
H11: Z | I11: Food Stream Solutions | J11: FC - Emerging Category | K11: Cabinet | L11: Actuators - Hydraulic Outlet | O11: BRL | S11: Electronic | T11: New Technology | U11: S Thambidurai | X11: LAR | Y11: 41640
H12: X | I12: Home Cleaning | J12: FC - Horizontal Axis Washer 27 | K12: Cabinet - Aesthetic | L12: Actuators - Recirculation | O12: CNY | S12: Glass | T12: Tradeoff Study | X12: China
H13: S | I13: Portable Appliances | J13: FC - Horizontal Axis Washer 60 | K13: Cabinet - Enclosure | L13: Air Traps | O13: EUR | S13: Harness | T13: Modeled Cost | U13: Luke Fitchner | X13: Europe East
I14: Storage Organization | J14: FC - Legacy and Specials | K14: Cabinet - Entrance | L14: Appliance Control Unit | S14: Metal | U14: James Barber | X14: Europe West
I15: Water Products | J15: FC - Vertical Axis Washer | K15: Cabinet - Top And Lid | L15: Appliance Control Unit - Expansion | S15: Motor | U15: Jeff Haselhoff | X15: India - Pune
I16: Air Treatment | J16: FP - Built In Cooktop | K16: Cavity | L16: Bake Pans | S16: Other | U16: Mark Young | X16: India - Pondicherry
J17: FP - Built In Oven | K17: Cavity Microwave | L17: Base - Condensing Dryer | S17: Packaging / Literature | U17: Ken Whise | X17: India - Faridabad
J18: FP - Emerging Category | K18: Controls | L18: Baskets - Cabinet | S18: Plastic | U18: Tony Molica
J19: FP - Freestanding Range | K19: Cooktop | L19: Baskets - Washer | S19: Rubber | U19: Chip Vander Ark
J20: FP - Microwave Oven - Built In | K20: Cooling System | L20: Bearings | U20: Heath Wall
J21: FP - Microwave Oven - Countertop | K21: Dispensing System | L21: Bellows | U21: Kelly Noland
J22: FP - Microwave Oven - Hood Combination | K22: Documentation | L22: Belt Tension System
J23: FSS - Bottom Mount | K23: Door | L23: Bezel Gravity Dispenser
J24: FSS - Emerging Category | K24: Door And Drawer | L24: Bins - Door
J25: FSS - Side by Side | K25: Drawer | L25: Blades
J26: FSS - Single Door | K26: Drive System | L26: Blower Active Vent
J27: FSS - Top Mount | K27: Dry System | L27: Blower Wheels | T27: multi-dependent drop-down in excel
J28: HC - Dishwasher | K28: Dryer Drum | L28: Blowers
J29: HC - Emerging Category | K29: Heater | L29: Body - Drum
J30: HC - Trash Compactor / Misc | K30: Hood - Microwave | L30: Bowls
J31: PA - Blender | K31: Hydraulic System - Distribution | L31: Brackets - Cross Top
J32: PA - Emerging Category | K32: Hydraulic System - Drain Assembly | L32: Brackets - Front Top
J33: PA - Hand Mixer | K33: Hydraulic System - Fill | L33: Brand Badges
J34: PA - Standmixer | K34: Hydraulic System - Inlet | L34: Break Inlet Siphon
J35: SO - Storage Organization | K35: Hydraulic System - Outlet | L35: Buckets - Twist Ice
J36: WP - Water Products | K36: Hydraulic System - Pump Sump Assembly And Heater | L36: Bulk Head Front
K37: Hydraulic System - Recirculation | L37: Bulk Head Rear
K38: Ice And Water | L38: Burner Box
K39: Interior Space Management - Racks | L39: Burner Coils
K40: Interior Space Management - Rails And Adjuster | L40: Burner Gas Oven
K41: Interior Space Management - Shelves And Bins | L41: Burners Induction
K42: Packaging | L42: Burners Radiant
...

Sheet Version History
A1: Change | B1: Date | C1: Responsible
A2: Added Data Validation to columns C, D, S, T, U, V & X | B2: 43259 | C2: Jeff
A3: Moved "Commodity Type" column next to "Type" column | B3: 43262 | C3: Jeff
A4: Added error check and message to column A
A5: Removed Module and Subsystem data
A6: Moved Process Control Type to Column Q | B6: 43266 | C6: Jeff
A7: Named column H | B7: 43272 | C7: Jeff
A8: Deleted column AH and AI
A9: Added formula for column AG | B9: 43273 | C9: Jeff
A10: Copied formulas through document
A11: Added project column and primary mfg region column | B11: 43278 | C11: Jeff
A12: Added data validation to column Q | B12: 43291 | C12: Jeff
A13: Updated formulas in columns in AC & AD | B13: 43292 | C13: Jeff
A14: Moved Date column and updated script file for checking required data | B14: 43356 | C14: Jeff & Onix
A15: Updated script to clear data and reinput formulas | B15: 43367 | C15: Jeff & Onix
A16: Added Romania, Thailand, and Vietnam to sheet | B16: 43438 | C16: Jeff
A17: Added July 2019 and deleted 2016 July, 2016 January and 2015 July to Economic Date | B17: 43691 | C17: Jeff
A18: Added 2020 January to Economic Date | B18: 43864 | C18: Tony

Sheet XDO_NOT_DELETE
A1: {=IFERROR(IF(ISBLANK('BOM Loader'!$Y11), "", transpose(INDIRECT(SUBSTITUTE(SUBSTITUTE('BOM Loader'!$Y11, " ", ""),"-", "")))), "")} -> Dryer | B1: HA Washer | C1: VA Washer | D1: FSOU | E1: Commercial Laundry
A2: {=IFERROR(IF(ISBLANK('BOM Loader'!$Y12), "", transpose(INDIRECT(SUBSTITUTE(SUBSTITUTE('BOM Loader'!$Y12, " ", ""),"-", "")))), "")}
A3: {=IFERROR(IF(ISBLANK('BOM Loader'!$Y13), "", transpose(INDIRECT(SUBSTITUTE(SUBSTITUTE('BOM Loader'!$Y13, " ", ""),"-", "")))), "")}
A4: {=IFERROR(IF(ISBLANK('BOM Loader'!$Y14), "", transpose(INDIRECT(SUBSTITUTE(SUBSTITUTE('BOM Loader'!$Y14, " ", ""),"-", "")))), "")}
A5: {=IFERROR(IF(ISBLANK('BOM Loader'!$Y15), "", transpose(INDIRECT(SUBSTITUTE(SUBSTITUTE('BOM Loader'!$Y15, " ", ""),"-", "")))), "")}
A6: {=IFERROR(IF(ISBLANK('BOM Loader'!$Y16), "", transpose(INDIRECT(SUBSTITUTE(SUBSTITUTE('BOM Loader'!$Y16, " ", ""),"-", "")))), "")}
A7: {=IFERROR(IF(ISBLANK('BOM Loader'!$Y17), "", transpose(INDIRECT(SUBSTITUTE(SUBSTITUTE('BOM Loader'!$Y17, " ", ""),"-", "")))), "")}
A8: {=IFERROR(IF(ISBLANK('BOM Loader'!$Y18), "", transpose(INDIRECT(SUBSTITUTE(SUBSTITUTE('BOM Loader'!$Y18, " ", ""),"-", "")))), "")}
A9: {=IFERROR(IF(ISBLANK('BOM Loader'!$Y19), "", transpose(INDIRECT(SUBSTITUTE(SUBSTITUTE('BOM Loader'!$Y19, " ", ""),"-", "")))), "")}
A10: {=IFERROR(IF(ISBLANK('BOM Loader'!$Y20), "", transpose(INDIRECT(SUBSTITUTE(SUBSTITUTE('BOM Loader'!$Y20, " ", ""),"-", "")))), "")}
A11: {=IFERROR(IF(ISBLANK('BOM Loader'!$Y21), "", transpose(INDIRECT(SUBSTITUTE(SUBSTITUTE('BOM Loader'!$Y21, " ", ""),"-", "")))), "")}
A12: {=IFERROR(IF(ISBLANK('BOM Loader'!$Y22), "", transpose(INDIRECT(SUBSTITUTE(SUBSTITUTE('BOM Loader'!$Y22, " ", ""),"-", "")))), "")}
A13: {=IFERROR(IF(ISBLANK('BOM Loader'!$Y23), "", transpose(INDIRECT(SUBSTITUTE(SUBSTITUTE('BOM Loader'!$Y23, " ", ""),"-", "")))), "")}
... A1000: {=IFERROR(IF(ISBLANK('BOM Loader'!$Y1010), "", transpose(INDIRECT(SUBSTITUTE(SUBSTITUTE('BOM Loader'!$Y1010, " ", ""),"-", "")))), "")}
